Workbook

Sheet Bundle Catalog
A1: Edly — Open edX Solution Bundles (Sales Catalog)
A2: 87 client-proven Open edX customizations (EDU-004–EDU-090) grouped into 15 sellable bundles. Click a bundle name for its detail sheet. Compiled 29 Aug 2026 from the master sales sheet.
A4: Bundle ID | B4: Bundle | C4: What it delivers (elevator pitch) | D4: Offer when the client asks about… | E4: Features | F4: Solution IDs | G4: Build hrs already engineered | H4: First-delivery hrs (est.) | I4: Repeat-delivery hrs (est.) | J4: Effort saved vs building new | K4: No-estimate items | L4: In-dev items | M4: Client accounts required (client-held) | N4: Pairs well with | O4: Bundle list price — FILL IN
A5: B01 | B5: Commerce & Monetization | C5: Everything a client needs to charge for learning: checkout through five payment gateways (including regional ones), storefront payments via WooCommerce, and time-based subscription access to courses. | D5: pricing / paid courses · payment gateways & checkout · subscriptions · selling in specific regions (e.g. Egypt via Cowpay) | E5: =COUNTA('B01 Commerce & Monetization'!$A$7:$A$13) -> 7 | F5: EDU-042, EDU-069–074 | G5: =SUM('B01 Commerce & Monetization'!$I$7:$I$13) -> 212 | H5: =SUM('B01 Commerce & Monetization'!$G$7:$G$13) -> 73 | I5: =SUM('B01 Commerce & Monetization'!$H$7:$H$13) -> 15 | J5: =IFERROR(1-H5/G5,"") -> 0.65566038 | K5: =COUNTBLANK('B01 Commerce & Monetization'!$G$7:$G$13) -> 0 | L5: =COUNTIF('B01 Commerce & Monetization'!$E$7:$E$13,"In Development") -> 0 | M5: Authorize.Net; Cowpay; Cybersource; PayPal; Stripe; Stripe (and WooCommerce) | N5: B14 (storefront), B10 (free trials)
A6: B02 | B6: Localization & Global Delivery | C6: Take one catalog global: translated course re-runs, AI translation of course content and platform strings, automatic language selection per course, and WPML-backed multilingual site content. | D6: multi-language platform · Arabic/French/Spanish content · AI translation · serving learners across countries | E6: =COUNTA('B02 Localization & Global'!$A$7:$A$11) -> 5 | F6: EDU-004, EDU-024–025, EDU-031, EDU-083 | G6: =SUM('B02 Localization & Global'!$I$7:$I$11) -> 2000 | H6: =SUM('B02 Localization & Global'!$G$7:$G$11) -> 181 | I6: =SUM('B02 Localization & Global'!$H$7:$H$11) -> 91 | J6: =IFERROR(1-H6/G6,"") -> 0.9095 | K6: =COUNTBLANK('B02 Localization & Global'!$G$7:$G$11) -> 0 | L6: =COUNTIF('B02 Localization & Global'!$E$7:$E$11,"In Development") -> 0 | M6: AI/LLM translation provider; LLM/translation provider; WPML | N6: B03 (AI), B14 (site)
A7: B03 | B7: AI Learning Experience | C7: Embed an AI tutor inside courses: per-unit AI chat attached to xBlocks plus a standalone chat xBlock, powered by an external AI chat service. | D7: AI tutor / chatbot inside courses · AI-assisted learner support | E7: =COUNTA('B03 AI Learning Experience'!$A$7:$A$8) -> 2 | F7: EDU-027–028 | G7: =SUM('B03 AI Learning Experience'!$I$7:$I$8) -> 440 | H7: =SUM('B03 AI Learning Experience'!$G$7:$G$8) -> 350 | I7: =SUM('B03 AI Learning Experience'!$H$7:$H$8) -> 350 | J7: =IFERROR(1-H7/G7,"") -> 0.20454545 | K7: =COUNTBLANK('B03 AI Learning Experience'!$G$7:$G$8) -> 0 | L7: =COUNTIF('B03 AI Learning Experience'!$E$7:$E$8,"In Development") -> 0 | M7: MIT Open Learning AI chat service; MIT Open Learning chat service | N7: B02 (AI translations)
A8: B04 | B8: Assessment & Credentialing | C8: Assess and certify beyond stock Open edX: staff-graded assignments, peer evaluations, live in-class responses, video-based rater certification, plus badges, Badgr and program certificates learners can show off. | D8: manual/staff grading · peer review · live quizzes · certification workflows · badges & certificates | E8: =COUNTA('B04 Assessment & Credentials'!$A$7:$A$13) -> 7 | F8: EDU-010, EDU-013, EDU-036, EDU-038, EDU-065, EDU-076, EDU-089 | G8: =SUM('B04 Assessment & Credentials'!$I$7:$I$13) -> 1244 | H8: =SUM('B04 Assessment & Credentials'!$G$7:$G$13) -> 325.25 | I8: =SUM('B04 Assessment & Credentials'!$H$7:$H$13) -> 159.25 | J8: =IFERROR(1-H8/G8,"") -> 0.73854502 | K8: =COUNTBLANK('B04 Assessment & Credentials'!$G$7:$G$13) -> 0 | L8: =COUNTIF('B04 Assessment & Credentials'!$E$7:$E$13,"In Development") -> 0 | M8: Badgr | N8: B05 (paths)
A9: B05 | B9: Learning Paths & Curriculum | C9: Structure the learning journey: electives learners choose, instructor-approved gated progression between sections, post-course recommendations, and course-to-program aggregation in Discovery. | D9: learning paths · electives · prerequisites / gated progression · programs · course recommendations | E9: =COUNTA('B05 Learning Paths'!$A$7:$A$10) -> 4 | F9: EDU-009, EDU-012, EDU-015, EDU-075 | G9: =SUM('B05 Learning Paths'!$I$7:$I$10) -> 940 | H9: =SUM('B05 Learning Paths'!$G$7:$G$10) -> 723 | I9: =SUM('B05 Learning Paths'!$H$7:$H$10) -> 358 | J9: =IFERROR(1-H9/G9,"") -> 0.23085106 | K9: =COUNTBLANK('B05 Learning Paths'!$G$7:$G$10) -> 0 | L9: =COUNTIF('B05 Learning Paths'!$E$7:$E$10,"In Development") -> 0 | M9: — | N9: B04 (credentials), B08 (ILT)
A10: B06 | B10: Interactive Content Pack (XBlocks) | C10: Fourteen ready-to-install XBlocks that make courses richer: polls, surveys, annotations, audio, PDF and Google Drive embeds, image explorer, step builder, word cloud, KWL, vector draw, reusable libraries, Google Calendar and Instruqt hands-on labs. | D10: more engaging course content · interactive activities · hands-on labs · embedding media & files | E10: =COUNTA('B06 Interactive Content Pack'!$A$7:$A$20) -> 14 | F10: EDU-044, EDU-049–061 | G10: =SUM('B06 Interactive Content Pack'!$I$7:$I$20) -> 256 | H10: =SUM('B06 Interactive Content Pack'!$G$7:$G$20) -> 87 | I10: =SUM('B06 Interactive Content Pack'!$H$7:$H$20) -> 23 | J10: =IFERROR(1-H10/G10,"") -> 0.66015625 | K10: =COUNTBLANK('B06 Interactive Content Pack'!$G$7:$G$20) -> 0 | L10: =COUNTIF('B06 Interactive Content Pack'!$E$7:$E$20,"In Development") -> 0 | M10: Instruqt | N10: B07 (engagement)
A11: B07 | B11: Learner Engagement & Feedback | C11: Keep learners active and heard: @-mention notifications in forums, learner-instructor feedback both ways, per-block feedback triggers, admin-curated asset libraries, and learner document uploads. | D11: community & forum features · collecting learner feedback · resource libraries · learner uploads | E11: =COUNTA('B07 Engagement & Feedback'!$A$7:$A$11) -> 5 | F11: EDU-006–008, EDU-011, EDU-032 | G11: =SUM('B07 Engagement & Feedback'!$I$7:$I$11) -> 695 | H11: =SUM('B07 Engagement & Feedback'!$G$7:$G$11) -> 356 | I11: =SUM('B07 Engagement & Feedback'!$H$7:$H$11) -> 210 | J11: =IFERROR(1-H11/G11,"") -> 0.48776978 | K11: =COUNTBLANK('B07 Engagement & Feedback'!$G$7:$G$11) -> 0 | L11: =COUNTIF('B07 Engagement & Feedback'!$E$7:$E$11,"In Development") -> 1 | M11: — | N11: B06 (content)
A12: B08 | B12: Academy Operations — ILT & Scheduling | C12: Run instructor-led and cohort training on Open edX: program/session management, calendars and scheduling, attendance tracking, and user administration. FBR feature set — currently in development. | D12: instructor-led training · sessions & timetables · attendance · cohort administration | E12: =COUNTA('B08 Academy Ops (ILT)'!$A$7:$A$10) -> 4 | F12: EDU-017–020 | G12: =SUM('B08 Academy Ops (ILT)'!$I$7:$I$10) -> 520 | H12: =SUM('B08 Academy Ops (ILT)'!$G$7:$G$10) -> 0 | I12: =SUM('B08 Academy Ops (ILT)'!$H$7:$H$10) -> 0 | J12: =IFERROR(1-H12/G12,"") -> 1 | K12: =COUNTBLANK('B08 Academy Ops (ILT)'!$G$7:$G$10) -> 4 | L12: =COUNTIF('B08 Academy Ops (ILT)'!$E$7:$E$10,"In Development") -> 4 | M12: — | N12: B05 (paths), B11 (admin)
A13: B09 | B13: Branding & White-Label | C13: Make the platform unmistakably theirs: runtime colour theming beyond light/dark, MFE slot customizations, and self-serve branding controls in the panel. | D13: white-label · custom branding & themes · UI customization without forking | E13: =COUNTA('B09 Branding & White-Label'!$A$7:$A$9) -> 3 | F13: EDU-005, EDU-039, EDU-062 | G13: =SUM('B09 Branding & White-Label'!$I$7:$I$9) -> 560 | H13: =SUM('B09 Branding & White-Label'!$G$7:$G$9) -> 44 | I13: =SUM('B09 Branding & White-Label'!$H$7:$H$9) -> 32 | J13: =IFERROR(1-H13/G13,"") -> 0.92142857 | K13: =COUNTBLANK('B09 Branding & White-Label'!$G$7:$G$9) -> 0 | L13: =COUNTIF('B09 Branding & White-Label'!$E$7:$E$9,"In Development") -> 0 | M13: — | N13: B10 (multisite)
A14: B10 | B14: Multisite & SaaS Operations | C14: Operate many portals from one place: unified super-admin panel with analytics, multisite management, DNS and custom-domain automation, and free-trial instance provisioning. | D14: multi-tenant / multiple academies · sub-portals per client or department · custom domains · trials | E14: =COUNTA('B10 Multisite & SaaS Ops'!$A$7:$A$11) -> 5 | F14: EDU-041, EDU-043, EDU-045, EDU-068, EDU-082 | G14: =SUM('B10 Multisite & SaaS Ops'!$I$7:$I$11) -> 804 | H14: =SUM('B10 Multisite & SaaS Ops'!$G$7:$G$11) -> 218 | I14: =SUM('B10 Multisite & SaaS Ops'!$H$7:$H$11) -> 40 | J14: =IFERROR(1-H14/G14,"") -> 0.72885572 | K14: =COUNTBLANK('B10 Multisite & SaaS Ops'!$G$7:$G$11) -> 0 | L14: =COUNTIF('B10 Multisite & SaaS Ops'!$E$7:$E$11,"In Development") -> 0 | M14: — | N14: B09 (branding), B11 (admin)
A15: B11 | B15: Admin Productivity Suite | C15: Cut back-office toil: impersonate learners for support, sysadmin dashboard, bulk registration and enrollment, panel-based course and user management, username changes, registration and forum toggles, and guided in-panel user tours. | D15: admin efficiency · support tooling · bulk operations · delegating admin to non-technical staff | E15: =COUNTA('B11 Admin Productivity'!$A$7:$A$15) -> 9 | F15: EDU-014, EDU-022–023, EDU-063, EDU-067, EDU-079–081, EDU-087 | G15: =SUM('B11 Admin Productivity'!$I$7:$I$15) -> 635 | H15: =SUM('B11 Admin Productivity'!$G$7:$G$15) -> 307 | I15: =SUM('B11 Admin Productivity'!$H$7:$H$15) -> 137 | J15: =IFERROR(1-H15/G15,"") -> 0.51653543 | K15: =COUNTBLANK('B11 Admin Productivity'!$G$7:$G$15) -> 0 | L15: =COUNTIF('B11 Admin Productivity'!$E$7:$E$15,"In Development") -> 0 | M15: Storylane | N15: B10 (multisite), B12 (reporting)
A16: B12 | B16: Analytics, Reporting & Growth | C16: See what is working and prove it: Google Analytics, Mixpanel and Segment instrumentation, HubSpot CRM logging, in-panel course and learner analytics, and CSV/PDF report downloads. | D16: analytics & dashboards · exportable reports · marketing/CRM data · measuring learner behaviour | E16: =COUNTA('B12 Analytics & Growth'!$A$7:$A$12) -> 6 | F16: EDU-046–048, EDU-064, EDU-077–078 | G16: =SUM('B12 Analytics & Growth'!$I$7:$I$12) -> 184 | H16: =SUM('B12 Analytics & Growth'!$G$7:$G$12) -> 64 | I16: =SUM('B12 Analytics & Growth'!$H$7:$H$12) -> 16 | J16: =IFERROR(1-H16/G16,"") -> 0.65217391 | K16: =COUNTBLANK('B12 Analytics & Growth'!$G$7:$G$12) -> 0 | L16: =COUNTIF('B12 Analytics & Growth'!$E$7:$E$12,"In Development") -> 0 | M16: Google Analytics; HubSpot; Mixpanel; Segment | N16: B10 (panel), B11 (admin)
A17: B13 | B17: Identity & SSO | C17: Frictionless, secure sign-in: social signup with Google, Azure, LinkedIn and Facebook, Azure AD B2C SSO, WordPress-to-LMS single sign-on, and an MIT-style social-auth backend as a reference implementation. | D17: SSO · social login · corporate identity (Azure AD B2C) · one login across site + LMS | E17: =COUNTA('B13 Identity & SSO'!$A$7:$A$10) -> 4 | F17: EDU-035, EDU-040, EDU-088, EDU-090 | G17: =SUM('B13 Identity & SSO'!$I$7:$I$10) -> 288 | H17: =SUM('B13 Identity & SSO'!$G$7:$G$10) -> 6 | I17: =SUM('B13 Identity & SSO'!$H$7:$H$10) -> 4 | J17: =IFERROR(1-H17/G17,"") -> 0.97916667 | K17: =COUNTBLANK('B13 Identity & SSO'!$G$7:$G$10) -> 1 | L17: =COUNTIF('B13 Identity & SSO'!$E$7:$E$10,"In Development") -> 0 | M17: Chosen social/SSO providers; Microsoft Azure AD B2C; WordPress | N17: B14 (WordPress)
A18: B14 | B18: WordPress Marketing Site | C18: A marketing front-end wired to the LMS: WordPress course catalog via Open edX APIs, blog, CloudFront/S3-backed media library, and a curated pack of essential WordPress plugins. | D18: marketing website · public course catalog · blog & SEO · landing pages | E18: =COUNTA('B14 WordPress Marketing'!$A$7:$A$10) -> 4 | F18: EDU-021, EDU-084–086 | G18: =SUM('B14 WordPress Marketing'!$I$7:$I$10) -> 72 | H18: =SUM('B14 WordPress Marketing'!$G$7:$G$10) -> 11 | I18: =SUM('B14 WordPress Marketing'!$H$7:$H$10) -> 3 | J18: =IFERROR(1-H18/G18,"") -> 0.84722222 | K18: =COUNTBLANK('B14 WordPress Marketing'!$G$7:$G$10) -> 1 | L18: =COUNTIF('B14 WordPress Marketing'!$E$7:$E$10,"In Development") -> 0 | M18: AWS (CloudFront/S3) and WordPress; Bundled WordPress plugins (several are paid tiers); WordPress | N18: B13 (SSO), B01 (commerce)
A19: B15 | B19: Platform Engineering & Integrations | C19: Keep the platform healthy and connected: Sentry monitoring, git and S3 course export and sync, a safe email deadbox for testing, an Open edX API client, plus Canvas and panel-level LTI interoperability. | D19: DevOps & monitoring · course backups & version control · LMS interoperability (Canvas, LTI) · API access | E19: =COUNTA('B15 Platform Eng & Integrations'!$A$7:$A$14) -> 8 | F19: EDU-016, EDU-026, EDU-029–030, EDU-033–034, EDU-037, EDU-066 | G19: =SUM('B15 Platform Eng & Integrations'!$I$7:$I$14) -> 968 | H19: =SUM('B15 Platform Eng & Integrations'!$G$7:$G$14) -> 34 | I19: =SUM('B15 Platform Eng & Integrations'!$H$7:$H$14) -> 18 | J19: =IFERROR(1-H19/G19,"") -> 0.96487603 | K19: =COUNTBLANK('B15 Platform Eng & Integrations'!$G$7:$G$14) -> 0 | L19: =COUNTIF('B15 Platform Eng & Integrations'!$E$7:$E$14,"In Development") -> 0 | M19: AWS; Canvas; GitHub; Sentry | N19: B11 (admin)
B20: ALL BUNDLES — TOTAL | E20: =SUM(E5:E19) -> 87 | G20: =SUM(G5:G19) -> 9818 | H20: =SUM(H5:H19) -> 2779.25 | I20: =SUM(I5:I19) -> 1456.25 | J20: =IFERROR(1-H20/G20,"") -> 0.716923 | K20: =SUM(K5:K19) -> 6 | L20: =SUM(L5:L19) -> 5
A22: HOW TO READ THIS CATALOG
A23: • Source & scope: built from the master sales sheet — 87 delivered Open edX customizations (EDU-004–EDU-090). The three "Example" rows (EDU-001–003) were excluded. Bundles are a sales lens; every feature can also be sold à la carte (see All Components).
A24: • Hours are the delivery team’s recorded engineering estimates. "First-delivery hrs" = "Est. first reuse (as recorded)" and includes plugin-conversion work where the source recorded it. "Repeat-delivery hrs" = per-client configuration once productized. Blank cells on bundle sheets = not recorded in source (counted under "No-estimate items"), so bundle totals understate by those items.
A25: • "Effort saved vs building new" = 1 − first-delivery ÷ already-engineered hours, over recorded items only — the reuse story to tell clients.
A26: • Figures are engineering hours only: add PM, QA and support overhead per your delivery standards before quoting. Items marked In Development (B08 FBR set, EDU-032) should be sold with a delivery-date caveat.
A27: • Third-party accounts are client-held; vendor fees are payable by the client and not quantified in the source.
A28: • YELLOW cells are for you to fill in: set each bundle’s list price — e.g. first-delivery hrs × blended rate, or a fixed fee such as "USD 15k + gateway fees".

Sheet B01 Commerce & Monetization
A1: B01 · Commerce & Monetization
A2: Pitch: Everything a client needs to charge for learning: checkout through five payment gateways (including regional ones), storefront payments via WooCommerce, and time-based subscription access to courses.
A3: Offer when the client asks about: pricing / paid courses · payment gateways & checkout · subscriptions · selling in specific regions (e.g. Egypt via Cowpay)
A4: Pairs well with: B14 (storefront), B10 (free trials)
A6: Solution ID | B6: Feature | C6: What it does | D6: Delivery form | E6: Status | F6: Std deployment time | G6: First-delivery hrs | H6: Repeat config hrs | I6: Original build hrs | J6: Reuse saving % (source) | K6: 3rd-party account required | L6: Integrations / dependencies | M6: Notes & limits | N6: Reference
A7: EDU-071 | B7: Stripe Payment Processor | C7: Payments can be processed via Stripe. | D7: Integration · Out-of-the-box | E7: Production | F7: 1 h | G7: 5 | H7: 1 | I7: 16 | J7: 0.938 | K7: Stripe | L7: Stripe. | M7: — | N7: —
A8: EDU-073 | B8: Paypal Payment Processor | C8: Payments can be processed via PayPal. | D8: Integration · Out-of-the-box | E8: Production | F8: 1 h | G8: 5 | H8: 1 | I8: 16 | J8: 0.938 | K8: PayPal | L8: PayPal. | M8: — | N8: —
A9: EDU-069 | B9: Authorizenet Payment Processor | C9: Payments can be processed via Authorizenet. | D9: Integration · Out-of-the-box | E9: Production | F9: 1 h | G9: 5 | H9: 1 | I9: 16 | J9: 0.938 | K9: Authorize.Net | L9: Authorize.Net. | M9: — | N9: —
A10: EDU-070 | B10: Cybersource Payment Processor | C10: Payments can be processed via Cybersource. | D10: Integration · Out-of-the-box | E10: Production | F10: 2 h | G10: 8 | H10: 2 | I10: 20 | J10: 0.9 | K10: Cybersource | L10: Cybersource. | M10: — | N10: —
A11: EDU-072 | B11: Cowpay Payment Processor | C11: Payments can be processed via an Egyptian Payment Processor called Cowpay (for the client IQLEAD). | D11: Integration · Custom Plugin | E11: Production | F11: 4 h | G11: 20 | H11: 4 | I11: 60 | J11: 0.933 | K11: Cowpay | L11: Cowpay. | M11: — | N11: —
A12: EDU-042 | B12: Stripe Integration within the platform | C12: Users can pay for the services themselves using the Stripe payment gateway. | D12: Integration · Out-of-the-box | E12: Production | F12: 2 h | G12: 10 | H12: 2 | I12: 24 | J12: 0.917 | K12: Stripe (and WooCommerce) | L12: Stripe; WordPress WooCommerce. | M12: Runs via WordPress WooCommerce storefront. | N12: —
A13: EDU-074 | B13: Subscription Feature in E-Commerce | C13: Learners can purchase time-based access to courses using the subscription feature. | D13: Mixed Feature | E13: Production | F13: 4 h | G13: 20 | H13: 4 | I13: 60 | J13: 0.933 | K13: — | L13: Open edX E-Commerce. | M13: Core/MFE changes — patched platform build; upgrade maintenance. | N13: —
B14: Bundle total | G14: =SUM(G7:G13) -> 73 | H14: =SUM(H7:H13) -> 15 | I14: =SUM(I7:I13) -> 212

Sheet B02 Localization & Global
A1: B02 · Localization & Global Delivery
A2: Pitch: Take one catalog global: translated course re-runs, AI translation of course content and platform strings, automatic language selection per course, and WPML-backed multilingual site content.
A3: Offer when the client asks about: multi-language platform · Arabic/French/Spanish content · AI translation · serving learners across countries
A4: Pairs well with: B03 (AI), B14 (site)
A6: Solution ID | B6: Feature | C6: What it does | D6: Delivery form | E6: Status | F6: Std deployment time | G6: First-delivery hrs | H6: Repeat config hrs | I6: Original build hrs | J6: Reuse saving % (source) | K6: 3rd-party account required | L6: Integrations / dependencies | M6: Notes & limits | N6: Reference
A7: EDU-004 | B7: Meta Translations | C7: Allow to create translated course re-runs | D7: Mixed Feature | E7: Production | F7: 14 business days | G7: 160 | H7: 80 | I7: 1600 | J7: 0.95 | K7: — | L7: — | M7: Core/MFE changes — patched platform build; upgrade maintenance. | Require Changes in Core (Edx-Platform, Authoring MFE and New Plugin App) | N7: https://github.com/wikimedia/edx-platform/issues/555
A8: EDU-031 | B8: AI generated Course Translations | C8: An Open edX plugin to translate course content into multiple languages to enhance accessibility for a global audience. | D8: Django App · Custom Plugin | E8: Production | F8: 2 h | G8: 2 | H8: 2 | I8: 160 | J8: 0.988 | K8: AI/LLM translation provider | L8: AI/LLM translation service (provider not named in source). | M8: — | N8: https://github.com/mitodl/open-edx-plugins/tree/main/src/ol_openedx_course_translations
A9: EDU-024 | B9: Open edX AI Static Translations | C9: An Open edX plugin that provides AI-powered static translation management. It syncs translation keys, translates them using LLM providers, and creates pull requests with translated content. | D9: Django App · Custom Plugin | E9: Production | F9: 2 h | G9: 2 | H9: 2 | I9: 120 | J9: 0.983 | K9: LLM/translation provider | L9: LLM translation providers; GitHub (raises pull requests). | M9: — | N9: https://github.com/mitodl/open-edx-plugins/tree/main/src/ol_openedx_ai_static_translations
A10: EDU-025 | B10: Open edX Auto Select Language | C10: An Open edX plugin to auto select the Open edX platform language based on the course language. | D10: Django App · Custom Plugin | E10: Production | F10: 4 h | G10: 4 | H10: 4 | I10: 80 | J10: 0.95 | K10: — | L10: MFE language-cookie configuration. | M10: MFE config to set the language cookies. | N10: https://github.com/mitodl/open-edx-plugins/tree/main/src/ol_openedx_auto_select_language
A11: EDU-083 | B11: Multi lingual support across platform | C11: Provides content in multiple languages via WPML and Open edX multilingual support. | D11: Mixed Feature · Out-of-the-box | E11: Production | F11: 3 h | G11: 13 | H11: 3 | I11: 40 | J11: 0.925 | K11: WPML | L11: WPML (WordPress); Open edX multilingual support. | M11: Core/MFE changes — patched platform build; upgrade maintenance. | N11: —
B12: Bundle total | G12: =SUM(G7:G11) -> 181 | H12: =SUM(H7:H11) -> 91 | I12: =SUM(I7:I11) -> 2000

Sheet B03 AI Learning Experience
A1: B03 · AI Learning Experience
A2: Pitch: Embed an AI tutor inside courses: per-unit AI chat attached to xBlocks plus a standalone chat xBlock, powered by an external AI chat service.
A3: Offer when the client asks about: AI tutor / chatbot inside courses · AI-assisted learner support
A4: Pairs well with: B02 (AI translations)
A6: Solution ID | B6: Feature | C6: What it does | D6: Delivery form | E6: Status | F6: Std deployment time | G6: First-delivery hrs | H6: Repeat config hrs | I6: Original build hrs | J6: Reuse saving % (source) | K6: 3rd-party account required | L6: Integrations / dependencies | M6: Notes & limits | N6: Reference
A7: EDU-027 | B7: Per block AI Tutor/Chat | C7: An xBlock aside to add MIT Open Learning AI chat into xBlocks. | D7: Django App · Custom Plugin | E7: Production | F7: 42 business days | G7: 250 | H7: 250 | I7: 320 | J7: 0.219 | K7: MIT Open Learning AI chat service | L7: MIT Open Learning AI chat service (external chat server + frontend drawer bundle). | M7: Requires external AI chat server + frontend drawer bundle; effort scales with course content. | N7: https://github.com/mitodl/open-edx-plugins/tree/main/src/ol_openedx_chat
A8: EDU-028 | B8: Open edX Chat xBlock | C8: An xBlock to add MIT Open Learning chat in courses. | D8: XBlock · Custom Plugin | E8: Production | F8: 17 business days | G8: 100 | H8: 100 | I8: 120 | J8: 0.167 | K8: MIT Open Learning chat service | L8: MIT Open Learning chat service. | M8: Requires external chat server + frontend drawer bundle (same stack as EDU-027). | N8: https://github.com/mitodl/open-edx-plugins/tree/main/src/ol_openedx_chat_xblock
B9: Bundle total | G9: =SUM(G7:G8) -> 350 | H9: =SUM(H7:H8) -> 350 | I9: =SUM(I7:I8) -> 440

Sheet B04 Assessment & Credentials
A1: B04 · Assessment & Credentialing
A2: Pitch: Assess and certify beyond stock Open edX: staff-graded assignments, peer evaluations, live in-class responses, video-based rater certification, plus badges, Badgr and program certificates learners can show off.
A3: Offer when the client asks about: manual/staff grading · peer review · live quizzes · certification workflows · badges & certificates
A4: Pairs well with: B05 (paths)
A6: Solution ID | B6: Feature | C6: What it does | D6: Delivery form | E6: Status | F6: Std deployment time | G6: First-delivery hrs | H6: Repeat config hrs | I6: Original build hrs | J6: Reuse saving % (source) | K6: 3rd-party account required | L6: Integrations / dependencies | M6: Notes & limits | N6: Reference
A7: EDU-038 | B7: Staff Graded Assignment XBlock | C7: An xBlock that provides staff graded assignments | D7: XBlock · Custom Plugin | E7: Production | F7: 1 h | G7: 1 | H7: 1 | I7: 320 | J7: 0.997 | K7: — | L7: — | M7: — | N7: https://github.com/mitodl/edx-sga
A8: EDU-089 | B8: Rater Certification XBlock | C8: Asynchronous video-based rater certification — users score observation videos against expert scores and are certified on like-score agreement | D8: XBlock · Existing Plugin (XBlock) | E8: Production | F8: 0.25 h | G8: 0.25 | H8: 0.25 | I8: 70 | J8: 0.996 | K8: — | L8: Client-hosted video source (per Dependencies). | M8: Per-reuse: create pools, attach videos, define dimensions, enter expert scores, set feedback copy per dimension × outcome, confirm thresholds. 15 min assumes client supplies expert scores/feedback in importable form. | N8: https://github.com/teachsim-lab/video-rater-xblock
A9: EDU-010 | B9: Evaluation Forms | C9: Allows learners to give evaluations to peers | D9: Mixed Feature | E9: Production | F9: 10 business days | G9: 120 | H9: 60 | I9: 150 | J9: 0.6 | K9: — | L9: — | M9: Core/MFE changes — patched platform build; upgrade maintenance. | N9: Toastmasters Azure DevOps (Private)
A10: EDU-036 | B10: Rapid Response xBlock Aside | C10: A django app that provides an xBlock aside for live responses on multiple choice problems | D10: Django App · Custom Plugin | E10: Production | F10: 2 h | G10: 2 | H10: 2 | I10: 240 | J10: 0.992 | K10: — | L10: — | M10: — | N10: https://github.com/mitodl/open-edx-plugins/tree/main/src/rapid_response_xblock
A11: EDU-013 | B11: Badges | C11: Assign badges to learners when they complete a specific section or course | D11: Mixed Feature | E11: Production | F11: 15 business days | G11: 180 | H11: 90 | I11: 400 | J11: 0.775 | K11: — | L11: — | M11: Core/MFE changes — patched platform build; upgrade maintenance. | N11: Toastmasters Azure DevOps (Private)
A12: EDU-065 | B12: Badgr Integration in Panel | C12: Learners can earn badges in Badgr and use these to show off their skills. | D12: Integration · Mixed Feature | E12: Production | F12: 2 h | G12: 6 | H12: 2 | I12: 16 | J12: 0.875 | K12: Badgr | L12: Badgr. | M12: — | N12: —
A13: EDU-076 | B13: Programs Certificates in Discovery | C13: Admins and course authors can set up certificates for completion of programs in Discovery. | D13: Django App · Mixed Feature | E13: Production | F13: 4 h | G13: 16 | H13: 4 | I13: 48 | J13: 0.917 | K13: — | L13: Open edX Discovery. | M13: — | N13: —
B14: Bundle total | G14: =SUM(G7:G13) -> 325.25 | H14: =SUM(H7:H13) -> 159.25 | I14: =SUM(I7:I13) -> 1244

Sheet B05 Learning Paths
A1: B05 · Learning Paths & Curriculum
A2: Pitch: Structure the learning journey: electives learners choose, instructor-approved gated progression between sections, post-course recommendations, and course-to-program aggregation in Discovery.
A3: Offer when the client asks about: learning paths · electives · prerequisites / gated progression · programs · course recommendations
A4: Pairs well with: B04 (credentials), B08 (ILT)
A6: Solution ID | B6: Feature | C6: What it does | D6: Delivery form | E6: Status | F6: Std deployment time | G6: First-delivery hrs | H6: Repeat config hrs | I6: Original build hrs | J6: Reuse saving % (source) | K6: 3rd-party account required | L6: Integrations / dependencies | M6: Notes & limits | N6: Reference
A7: EDU-009 | B7: Electives | C7: Allows instructor add a subsections as electives. Learner can select electives of their choice. | D7: Mixed Feature | E7: Production | F7: 25 business days | G7: 300 | H7: 150 | I7: 250 | J7: 0.4 | K7: — | L7: — | M7: Core/MFE changes — patched platform build; upgrade maintenance. | N7: Toastmasters Azure DevOps (Private)
A8: EDU-015 | B8: Section Completion (Approval and Reversal) | C8: Custom completion method i.e. complete section and create a approval request. Instructor can approve / deny it. Learner cannot view next section, until previous section is marked as completed | D8: Mixed Feature | E8: Production | F8: 20 business days | G8: 240 | H8: 120 | I8: 500 | J8: 0.76 | K8: — | L8: — | M8: Core/MFE changes — patched platform build; upgrade maintenance. | N8: Toastmasters Azure DevOps (Private)
A9: EDU-012 | B9: Suggested Learning | C9: When learner completes a course, suggested courses are shown to learners. Suggested courses are picked based on instructors recommendation | D9: Mixed Feature | E9: Production | F9: 15 business days | G9: 170 | H9: 85 | I9: 150 | J9: 0.433 | K9: — | L9: — | M9: Core/MFE changes — patched platform build; upgrade maintenance. | N9: Toastmasters Azure DevOps (Private)
A10: EDU-075 | B10: Programs Integration in Discovery | C10: Admins and course authors can aggregate courses into programs easily in Discovery. | D10: Django App · Mixed Feature | E10: Production | F10: 3 h | G10: 13 | H10: 3 | I10: 40 | J10: 0.925 | K10: — | L10: Open edX Discovery. | M10: — | N10: —
B11: Bundle total | G11: =SUM(G7:G10) -> 723 | H11: =SUM(H7:H10) -> 358 | I11: =SUM(I7:I10) -> 940

Sheet B06 Interactive Content Pack
A1: B06 · Interactive Content Pack (XBlocks)
A2: Pitch: Fourteen ready-to-install XBlocks that make courses richer: polls, surveys, annotations, audio, PDF and Google Drive embeds, image explorer, step builder, word cloud, KWL, vector draw, reusable libraries, Google Calendar and Instruqt hands-on labs.
A3: Offer when the client asks about: more engaging course content · interactive activities · hands-on labs · embedding media & files
A4: Pairs well with: B07 (engagement)
A6: Solution ID | B6: Feature | C6: What it does | D6: Delivery form | E6: Status | F6: Std deployment time | G6: First-delivery hrs | H6: Repeat config hrs | I6: Original build hrs | J6: Reuse saving % (source) | K6: 3rd-party account required | L6: Integrations / dependencies | M6: Notes & limits | N6: Reference
A7: EDU-057 | B7: Poll XBlock | C7: Gathers feedback to improve course content and delivery by understanding learner needs and preferences. | D7: XBlock · Out-of-the-box | E7: Production | F7: 1 h | G7: 3 | H7: 1 | I7: 8 | J7: 0.875 | K7: — | L7: — | M7: — | N7: —
A8: EDU-052 | B8: Survey XBlock | C8: Gathers feedback to improve course content and delivery by understanding learner needs and preferences. | D8: XBlock · Out-of-the-box | E8: Production | F8: 1 h | G8: 3 | H8: 1 | I8: 8 | J8: 0.875 | K8: — | L8: — | M8: — | N8: —
A9: EDU-050 | B9: Annotation XBlock | C9: Promotes active learning and critical thinking by encouraging learners to engage with specific parts of the text through targeted questions. | D9: XBlock · Out-of-the-box | E9: Production | F9: 1 h | G9: 3 | H9: 1 | I9: 8 | J9: 0.875 | K9: — | L9: — | M9: — | N9: —
A10: EDU-049 | B10: Word Cloud XBlock | C10: Encourages engagement and interaction by providing a visual summary of content that can help in better comprehension and retention. | D10: XBlock · Out-of-the-box | E10: Production | F10: 1 h | G10: 3 | H10: 1 | I10: 8 | J10: 0.875 | K10: — | L10: — | M10: — | N10: —
A11: EDU-056 | B11: Image Explorer XBlock | C11: Allows targeted definitions with visuals to provide an easier way of understanding for the learners. | D11: XBlock · Out-of-the-box | E11: Production | F11: 1 h | G11: 3 | H11: 1 | I11: 8 | J11: 0.875 | K11: — | L11: — | M11: — | N11: —
A12: EDU-058 | B12: Step Builder XBlock | C12: Avoids overwhelming the learner by breaking down a problem in smaller chunks. | D12: XBlock · Out-of-the-box | E12: Production | F12: 1 h | G12: 3 | H12: 1 | I12: 8 | J12: 0.875 | K12: — | L12: — | M12: — | N12: —
A13: EDU-060 | B13: Knowledge-Wonder-Learn XBlock | C13: Gauges course effectiveness by comparing learners' initial knowledge and questions with what they have learned, providing a clear measure of knowledge acquisition throughout the course. | D13: XBlock · Out-of-the-box | E13: Production | F13: 3 h | G13: 13 | H13: 3 | I13: 40 | J13: 0.925 | K13: — | L13: — | M13: — | N13: —
A14: EDU-053 | B14: Vector Draw XBlock | C14: Enriches the learning experience by providing an interactive way of assessing the learners. | D14: XBlock · Out-of-the-box | E14: Production | F14: 1 h | G14: 3 | H14: 1 | I14: 8 | J14: 0.875 | K14: — | L14: — | M14: — | N14: —
A15: EDU-054 | B15: Audio XBlock | C15: Enhances the learning experience by allowing learners to listen to course content within the LMS. | D15: XBlock · Out-of-the-box | E15: Production | F15: 1 h | G15: 3 | H15: 1 | I15: 8 | J15: 0.875 | K15: — | L15: — | M15: — | N15: —
A16: EDU-061 | B16: PDF XBlock | C16: Facilitates seamless access to embedded PDF files without having to leave the webpage. | D16: XBlock · Out-of-the-box | E16: Production | F16: 1 h | G16: 3 | H16: 1 | I16: 8 | J16: 0.875 | K16: — | L16: — | M16: — | N16: —
A17: EDU-055 | B17: Google Drive XBlock | C17: Enriches the learning experience by providing an easy way to integrate Google Drive content. | D17: XBlock · Out-of-the-box | E17: Production | F17: 2 h | G17: 8 | H17: 2 | I17: 24 | J17: 0.917 | K17: — | L17: Google Drive. | M17: — | N17: —
A18: EDU-059 | B18: Custom Library XBlock | C18: Allows the use of a unified resource without having to create it repeatedly | D18: XBlock · Out-of-the-box | E18: Production | F18: 1 h | G18: 3 | H18: 1 | I18: 8 | J18: 0.875 | K18: — | L18: — | M18: — | N18: —
... A20: EDU-044 | B20: Instruqt XBlock Integration | C20: Enables an interactive and enriched learning experiences by integrating the capabilities of Instruqt all within the LMS. | D20: XBlock · Custom Plugin | E20: Production | F20: 6 h | G20: 26 | H20: 6 | I20: 80 | J20: 0.925 | K20: Instruqt | L20: Instruqt. | M20: — | N20: —
B21: Bundle total | G21: =SUM(G7:G20) -> 87 | H21: =SUM(H7:H20) -> 23 | I21: =SUM(I7:I20) -> 256

Sheet B07 Engagement & Feedback
A1: B07 · Learner Engagement & Feedback
A2: Pitch: Keep learners active and heard: @-mention notifications in forums, learner-instructor feedback both ways, per-block feedback triggers, admin-curated asset libraries, and learner document uploads.
A3: Offer when the client asks about: community & forum features · collecting learner feedback · resource libraries · learner uploads
A4: Pairs well with: B06 (content)
A6: Solution ID | B6: Feature | C6: What it does | D6: Delivery form | E6: Status | F6: Std deployment time | G6: First-delivery hrs | H6: Repeat config hrs | I6: Original build hrs | J6: Reuse saving % (source) | K6: 3rd-party account required | L6: Integrations / dependencies | M6: Notes & limits | N6: Reference
A7: EDU-006 | B7: Ping user in discussion forum | C7: Enables users to select and mention users in a discussion post, which sends a notification by email or by the site notification feature introduced in Ulmo. | D7: Tutor Plugin · Out-of-the-box | E7: Production | F7: Not recorded | G7: 16 | I7: 40 | J7: 1 | K7: — | L7: Email notifications; Open edX site notifications (Ulmo). | M7: — | N7: https://github.com/wikimedia/edx-platform/issues/522
A8: EDU-011 | B8: Feedback | C8: Allows learners to give feedbacks to instructors and vice versa | D8: Mixed Feature | E8: Production | F8: 7 business days | G8: 80 | H8: 40 | I8: 120 | J8: 0.667 | K8: — | L8: — | M8: Core/MFE changes — patched platform build; upgrade maintenance. | N8: Toastmasters Azure DevOps (Private)
A9: EDU-032 | B9: Block level learner feedback | C9: An Open edX plugin that adds a per-block "Send feedback" trigger to applicable leaf blocks in the LMS via an XBlockAside. | D9: Django App · Custom Plugin | E9: In Development | F9: 14 business days | G9: 80 | H9: 80 | I9: 160 | J9: 0.5 | K9: — | L9: — | M9: Depends on extra MFE customizations. | N9: https://github.com/mitodl/open-edx-plugins/tree/main/src/ol_openedx_feedback
A10: EDU-007 | B10: Assets Management | C10: Allows admin to create assets that are visible to learners. Each asset can have multiple categories and sub-categories | D10: Mixed Feature | E10: Production | F10: 9 business days | G10: 100 | H10: 50 | I10: 275 | J10: 0.818 | K10: — | L10: — | M10: Core/MFE changes — patched platform build; upgrade maintenance. | N10: Toastmasters Azure DevOps (Private)
A11: EDU-008 | B11: Documents | C11: User can upload their learning documents and can view them on platform | D11: Mixed Feature | E11: Production | F11: 7 business days | G11: 80 | H11: 40 | I11: 100 | J11: 0.6 | K11: — | L11: — | M11: Core/MFE changes — patched platform build; upgrade maintenance. | N11: Toastmasters Azure DevOps (Private)
B12: Bundle total | G12: =SUM(G7:G11) -> 356 | H12: =SUM(H7:H11) -> 210 | I12: =SUM(I7:I11) -> 695

Sheet B08 Academy Ops (ILT)
A1: B08 · Academy Operations — ILT & Scheduling
A2: Pitch: Run instructor-led and cohort training on Open edX: program/session management, calendars and scheduling, attendance tracking, and user administration. FBR feature set — currently in development.
A3: Offer when the client asks about: instructor-led training · sessions & timetables · attendance · cohort administration
A4: Pairs well with: B05 (paths), B11 (admin)
A6: Solution ID | B6: Feature | C6: What it does | D6: Delivery form | E6: Status | F6: Std deployment time | G6: First-delivery hrs | H6: Repeat config hrs | I6: Original build hrs | J6: Reuse saving % (source) | K6: 3rd-party account required | L6: Integrations / dependencies | M6: Notes & limits | N6: Reference
A7: EDU-020 | B7: Program | C7: Create and manage programs, courses, sessions, schedules, and learner enrollments. | D7: Mixed Feature | E7: In Development | F7: Not recorded | I7: 80 | K7: — | L7: — | M7: Core/MFE changes — patched platform build; upgrade maintenance. | N7: https://github.com/edly-io/tutor-contrib-fbr/tree/master/tutorfbr/templates/fbr/openedx-features-fbr
A8: EDU-018 | B8: Calendar Management | C8: Manage and schedule sessions, events, holidays, and important activities within the LMS. | D8: Mixed Feature | E8: In Development | F8: Not recorded | I8: 160 | K8: — | L8: — | M8: Core/MFE changes — patched platform build; upgrade maintenance. | N8: https://github.com/edly-io/tutor-contrib-fbr/tree/master/tutorfbr/templates/fbr/openedx-features-fbr
A9: EDU-019 | B9: Attendance | C9: Track and manage learner attendance for scheduled sessions, including attendance status and records. | D9: Mixed Feature | E9: In Development | F9: Not recorded | I9: 180 | K9: — | L9: — | M9: Core/MFE changes — patched platform build; upgrade maintenance. | N9: https://github.com/edly-io/tutor-contrib-fbr/tree/master/tutorfbr/templates/fbr/openedx-features-fbr
A10: EDU-017 | B10: User Management | C10: Manage users, their profiles, roles, permissions, status, and access within the Open edX LMS. | D10: Mixed Feature | E10: In Development | F10: Not recorded | I10: 100 | K10: — | L10: — | M10: Core/MFE changes — patched platform build; upgrade maintenance. | N10: https://github.com/edly-io/tutor-contrib-fbr/tree/master/tutorfbr/templates/fbr/openedx-features-fbr
B11: Bundle total | G11: =SUM(G7:G10) -> 0 | H11: =SUM(H7:H10) -> 0 | I11: =SUM(I7:I10) -> 520

Sheet B09 Branding & White-Label
A1: B09 · Branding & White-Label
A2: Pitch: Make the platform unmistakably theirs: runtime colour theming beyond light/dark, MFE slot customizations, and self-serve branding controls in the panel.
A3: Offer when the client asks about: white-label · custom branding & themes · UI customization without forking
A4: Pairs well with: B10 (multisite)
A6: Solution ID | B6: Feature | C6: What it does | D6: Delivery form | E6: Status | F6: Std deployment time | G6: First-delivery hrs | H6: Repeat config hrs | I6: Original build hrs | J6: Reuse saving % (source) | K6: 3rd-party account required | L6: Integrations / dependencies | M6: Notes & limits | N6: Reference
A7: EDU-005 | B7: Dynamic Theming | C7: Support to change color at runtime (not just light and dark mode) | D7: Mixed Feature | E7: Production | F7: 2 business days | G7: 8 | H7: 8 | I7: 200 | J7: 0.96 | K7: — | L7: Accounts MFE plugin slot; Paragon design tokens consumed by all MFEs. | M7: Custom tutor plugin, django app, and a custom React package | The migration to a tutor plugin would essentially be a rewrite from scratch, but once implemented would be a lot easier to port for different clients | N7: Toastmasters Azure DevOps (Private)
A8: EDU-039 | B8: MFE Customizations | C8: Customized MFEs using MFE Slot implementations | D8: MFE (Frontend) · Standalone Module | E8: Production | F8: 4 business days | G8: 20 | H8: 20 | I8: 320 | J8: 0.938 | K8: — | L8: MFE slot configuration. | M8: — | N8: https://github.com/mitodl/lehrer/tree/main/deployments/mit-ol/mfe_slot_config/legacy
A9: EDU-062 | B9: Site Customizations in Panel | C9: Site admins can easily handle the branding for the LMS using Theme accessibility in panel settings. | D9: Django App · Mixed Feature | E9: Production | F9: 4 h | G9: 16 | H9: 4 | I9: 40 | J9: 0.9 | K9: — | L9: — | M9: Requires Edly multi-tenant architecture. | N9: —
B10: Bundle total | G10: =SUM(G7:G9) -> 44 | H10: =SUM(H7:H9) -> 32 | I10: =SUM(I7:I9) -> 560

Sheet B10 Multisite & SaaS Ops
A1: B10 · Multisite & SaaS Operations
A2: Pitch: Operate many portals from one place: unified super-admin panel with analytics, multisite management, DNS and custom-domain automation, and free-trial instance provisioning.
A3: Offer when the client asks about: multi-tenant / multiple academies · sub-portals per client or department · custom domains · trials
A4: Pairs well with: B09 (branding), B11 (admin)
A6: Solution ID | B6: Feature | C6: What it does | D6: Delivery form | E6: Status | F6: Std deployment time | G6: First-delivery hrs | H6: Repeat config hrs | I6: Original build hrs | J6: Reuse saving % (source) | K6: 3rd-party account required | L6: Integrations / dependencies | M6: Notes & limits | N6: Reference
A7: EDU-041 | B7: Admin Panel | C7: Super Admins can manage multisite and view analytics using one unified dashboard. | D7: Mixed Feature | E7: Production | F7: 3 business days | G7: 96 | H7: 16 | I7: 420 | J7: 0.962 | K7: — | L7: — | M7: Core/MFE changes — patched platform build; upgrade maintenance. | N7: —
A8: EDU-045 | B8: Multisite Features | C8: Simplifies the management of multiple learning environments, offering tailored customization and content while centralizing user management and access control. | D8: Mixed Feature · Custom Plugin | E8: Production | F8: 2 business days | G8: 48 | H8: 8 | I8: 200 | J8: 0.96 | K8: — | L8: — | M8: — | N8: —
A9: EDU-043 | B9: DNS Automation | C9: Users can add custom domains for all pages of their platforms using the Admin dashboard. | D9: Django App · Custom Plugin | E9: Production | F9: 2 business days | G9: 40 | H9: 8 | I9: 80 | J9: 0.9 | K9: — | L9: DNS provider (custom domain automation). | M9: — | N9: —
A10: EDU-068 | B10: Custom Domain Updates in Panel | C10: Admins can easily Generate DNS entries required to set up custom domains via the panel. | D10: Django App · Mixed Feature | E10: Production | F10: 2 h | G10: 8 | H10: 2 | I10: 24 | J10: 0.917 | K10: — | L10: — | M10: — | N10: —
A11: EDU-082 | B11: Free Trial Instance in Panel | C11: Accesses the free trial instance directly from the panel. | D11: Django App · Mixed Feature | E11: Production | F11: 6 h | G11: 26 | H11: 6 | I11: 80 | J11: 0.925 | K11: — | L11: — | M11: — | N11: —
B12: Bundle total | G12: =SUM(G7:G11) -> 218 | H12: =SUM(H7:H11) -> 40 | I12: =SUM(I7:I11) -> 804

Sheet B11 Admin Productivity
A1: B11 · Admin Productivity Suite
A2: Pitch: Cut back-office toil: impersonate learners for support, sysadmin dashboard, bulk registration and enrollment, panel-based course and user management, username changes, registration and forum toggles, and guided in-panel user tours.
A3: Offer when the client asks about: admin efficiency · support tooling · bulk operations · delegating admin to non-technical staff
A4: Pairs well with: B10 (multisite), B12 (reporting)
A6: Solution ID | B6: Feature | C6: What it does | D6: Delivery form | E6: Status | F6: Std deployment time | G6: First-delivery hrs | H6: Repeat config hrs | I6: Original build hrs | J6: Reuse saving % (source) | K6: 3rd-party account required | L6: Integrations / dependencies | M6: Notes & limits | N6: Reference
A7: EDU-014 | B7: User Impersonation | C7: Allows admin to access platform as learner | D7: Mixed Feature | E7: Production | F7: 20 business days | G7: 240 | H7: 120 | I7: 275 | J7: 0.564 | K7: — | L7: — | M7: Core/MFE changes — patched platform build; upgrade maintenance. | N7: Toastmasters Azure DevOps (Private)
A8: EDU-022 | B8: Sysadmin | C8: An open edx plugin that provides sysadmin dashboard with features like Register Users, Delete Courses, Git Import course, and Git Auto Reload course. | D8: Django App · Custom Plugin | E8: Production | F8: 1 h | G8: 1 | H8: 1 | I8: 120 | J8: 0.992 | K8: — | L8: Git repository (course import and auto-reload). | M8: — | N8: https://github.com/mitodl/open-edx-plugins/tree/main/src/edx_sysadmin
A9: EDU-063 | B9: Bulk Registration and Enrollment in Panel | C9: Site admins can register and enroll learners in bulk using the panel. | D9: Django App · Mixed Feature | E9: Production | F9: 3 h | G9: 11 | H9: 3 | I9: 32 | J9: 0.906 | K9: — | L9: — | M9: — | N9: —
A10: EDU-079 | B10: Course Management in Panel | C10: Admins and course authors can manage courses directly from the panel, | D10: Django App · Mixed Feature | E10: Production | F10: 4 h | G10: 20 | H10: 4 | I10: 60 | J10: 0.933 | K10: — | L10: — | M10: — | N10: —
A11: EDU-080 | B11: User Management in Panel | C11: Admins and course authors can manage users directly from the panel, | D11: Django App · Mixed Feature | E11: Production | F11: 4 h | G11: 20 | H11: 4 | I11: 60 | J11: 0.933 | K11: — | L11: — | M11: — | N11: —
A12: EDU-023 | B12: Username changer | C12: A plugin to enable update usernames through admin panel in Open edX (and other apps that log into Open edX via OAuth). | D12: Django App · Custom Plugin | E12: Production | F12: 1 h | G12: 1 | H12: 1 | I12: 40 | J12: 0.975 | K12: — | L12: — | M12: — | N12: https://github.com/mitodl/open-edx-plugins/tree/main/src/edx_username_changer
A13: EDU-081 | B13: Toggle Public Registration in Panel | C13: Enables or disables public registration for the LMS directly from the panel. | D13: Django App · Mixed Feature | E13: Production | F13: 1 h | G13: 3 | H13: 1 | I13: 8 | J13: 0.875 | K13: — | L13: — | M13: — | N13: —
A14: EDU-067 | B14: Discussion Forum Toggle in panel | C14: Admins can easily enable/disable discussion forums directly from the panel. | D14: Django App · Mixed Feature | E14: Production | F14: 1 h | G14: 5 | H14: 1 | I14: 16 | J14: 0.938 | K14: — | L14: — | M14: — | N14: —
A15: EDU-087 | B15: User Guides for Learners and Instructors in Panel | C15: The Edly Panel has a Storylane Self Service User Guide shown to users. | D15: Other · Standalone Module | E15: Production | F15: 2 h | G15: 6 | H15: 2 | I15: 24 | J15: 0.917 | K15: Storylane | L15: Storylane. | M15: — | N15: —
B16: Bundle total | G16: =SUM(G7:G15) -> 307 | H16: =SUM(H7:H15) -> 137 | I16: =SUM(I7:I15) -> 635

Sheet B12 Analytics & Growth
A1: B12 · Analytics, Reporting & Growth
A2: Pitch: See what is working and prove it: Google Analytics, Mixpanel and Segment instrumentation, HubSpot CRM logging, in-panel course and learner analytics, and CSV/PDF report downloads.
A3: Offer when the client asks about: analytics & dashboards · exportable reports · marketing/CRM data · measuring learner behaviour
A4: Pairs well with: B10 (panel), B11 (admin)
A6: Solution ID | B6: Feature | C6: What it does | D6: Delivery form | E6: Status | F6: Std deployment time | G6: First-delivery hrs | H6: Repeat config hrs | I6: Original build hrs | J6: Reuse saving % (source) | K6: 3rd-party account required | L6: Integrations / dependencies | M6: Notes & limits | N6: Reference
A7: EDU-048 | B7: Google Analytics Integration | C7: Provides detailed insights into user acquisition, behavior, and conversions allowing Edly to optimize the platform based on real user interactions. | D7: Integration · Out-of-the-box | E7: Production | F7: 1 h | G7: 5 | H7: 1 | I7: 16 | J7: 0.938 | K7: Google Analytics | L7: Google Analytics. | M7: — | N7: —
A8: EDU-046 | B8: Mixpanel Integration | C8: Provides detailed insights into user behavior, allowing Edly to optimize the platform based on real user interactions. | D8: Integration · Mixed Feature | E8: Production | F8: 4 h | G8: 16 | H8: 4 | I8: 40 | J8: 0.9 | K8: Mixpanel | L8: Mixpanel. | M8: — | N8: —
A9: EDU-064 | B9: Segment Integration in Panel | C9: Course authors and site admins can add segment's key that can be used to access users interaction data specific to the segment. This data can be analyzed in a variety of analytics tools. | D9: Integration · Mixed Feature | E9: Production | F9: 2 h | G9: 8 | H9: 2 | I9: 24 | J9: 0.917 | K9: Segment | L9: Segment (and downstream analytics tools). | M9: — | N9: —
A10: EDU-047 | B10: Hubspot Integration | C10: Allows Edly to manage and keep a record of client calls. | D10: Integration · Mixed Feature | E10: Production | F10: 4 h | G10: 16 | H10: 4 | I10: 48 | J10: 0.917 | K10: HubSpot | L10: HubSpot. | M10: — | N10: —
A11: EDU-077 | B11: Courses & Learner Analytics | C11: Admins and course authors can review analytics for course specific aspects directly in the panel | D11: Integration · Out-of-the-box | E11: Production | F11: 2 h | G11: 8 | H11: 2 | I11: 24 | J11: 0.917 | K11: — | L11: — | M11: — | N11: —
A12: EDU-078 | B12: CSV/PDF Reports in Panel | C12: Admins and course authors can download analytical reports for course and/or learners in CSV/PDF format. | D12: Django App · Mixed Feature | E12: Production | F12: 3 h | G12: 11 | H12: 3 | I12: 32 | J12: 0.906 | K12: — | L12: — | M12: — | N12: —
B13: Bundle total | G13: =SUM(G7:G12) -> 64 | H13: =SUM(H7:H12) -> 16 | I13: =SUM(I7:I12) -> 184

Sheet B13 Identity & SSO
A1: B13 · Identity & SSO
A2: Pitch: Frictionless, secure sign-in: social signup with Google, Azure, LinkedIn and Facebook, Azure AD B2C SSO, WordPress-to-LMS single sign-on, and an MIT-style social-auth backend as a reference implementation.
A3: Offer when the client asks about: SSO · social login · corporate identity (Azure AD B2C) · one login across site + LMS
A4: Pairs well with: B14 (WordPress)
A6: Solution ID | B6: Feature | C6: What it does | D6: Delivery form | E6: Status | F6: Std deployment time | G6: First-delivery hrs | H6: Repeat config hrs | I6: Original build hrs | J6: Reuse saving % (source) | K6: 3rd-party account required | L6: Integrations / dependencies | M6: Notes & limits | N6: Reference
A7: EDU-040 | B7: Social Signup SSO (Google, MS Azure, LinkedIn, Facebook) | C7: Integrates SSO providers like Google, MS Azure, LinkedIn, and Facebook for easy registration and login. | D7: Other · Custom Plugin | E7: Production | F7: Not recorded | I7: 80 | K7: Chosen social/SSO providers | L7: Google, Microsoft Azure, LinkedIn, Facebook (social signup / SSO). | M7: — | N7: —
A8: EDU-088 | B8: SSO with azure b2c | C8: Single sign on with azure b2c | D8: SSO · Standalone Module | E8: Production | F8: 1 h | G8: 3 | H8: 1 | I8: 24 | K8: Microsoft Azure AD B2C | L8: Microsoft Azure AD B2C. | M8: — | N8: —
A9: EDU-090 | B9: WordPress SSO | C9: Single sign-on between a client WordPress site and Open edX — users authenticate once and move between the marketing/community site and the LMS without re-login | D9: Authentication / Integration · Existing Plugin | E9: Production | F9: 1 h | G9: 1 | H9: 1 | I9: 24 | J9: 0.958 | K9: WordPress | L9: WordPress (OAuth2 single sign-on). | M9: ~1 h per reuse: register the OAuth client on both sides, set site URLs and redirect/callback paths, map user attributes, smoke-test login both directions. Assumes client already has WordPress admin access and DNS/SSL in place. | N9: https://github.com/teachsim-lab/oauth-djangoapp
A10: EDU-035 | B10: Social Auth | C10: An Open edX plugin implementing MIT social auth backend | D10: Django App · Custom Plugin | E10: Production | F10: 2 h | G10: 2 | H10: 2 | I10: 160 | J10: 0.988 | K10: — | L10: MIT social auth backend; companion auth plugin (openedx_companion_auth). | M10: MIT-specific reference implementation; pair with openedx_companion_auth. | N10: https://github.com/mitodl/open-edx-plugins/tree/main/src/ol_social_auth
B11: Bundle total | G11: =SUM(G7:G10) -> 6 | H11: =SUM(H7:H10) -> 4 | I11: =SUM(I7:I10) -> 288

Sheet B14 WordPress Marketing
A1: B14 · WordPress Marketing Site
A2: Pitch: A marketing front-end wired to the LMS: WordPress course catalog via Open edX APIs, blog, CloudFront/S3-backed media library, and a curated pack of essential WordPress plugins.
A3: Offer when the client asks about: marketing website · public course catalog · blog & SEO · landing pages
A4: Pairs well with: B13 (SSO), B01 (commerce)
A6: Solution ID | B6: Feature | C6: What it does | D6: Delivery form | E6: Status | F6: Std deployment time | G6: First-delivery hrs | H6: Repeat config hrs | I6: Original build hrs | J6: Reuse saving % (source) | K6: 3rd-party account required | L6: Integrations / dependencies | M6: Notes & limits | N6: Reference
A7: EDU-021 | B7: Wordpress Integration | C7: Integrate a CMS like Wordpress with open edx apis for course catalog and other pages | D7: Integration · Standalone Module | E7: Production | F7: Not recorded | I7: 40 | K7: WordPress | L7: WordPress (course catalog and pages via Open edX APIs). | M7: — | N7: —
A8: EDU-085 | B8: WP Blog Integration in Edly | C8: Creates and manages blogs using WordPress Blog functionality. | D8: Integration · Out-of-the-box | E8: Production | F8: 1 h | G8: 3 | H8: 1 | I8: 8 | J8: 0.875 | K8: WordPress | L8: WordPress (blog). | M8: — | N8: —
A9: EDU-084 | B9: WP Media Library | C9: Ensures a robust media library for WordPress backed by Amazon CloudFront and S3. | D9: Integration · Out-of-the-box | E9: Production | F9: 1 h | G9: 3 | H9: 1 | I9: 8 | J9: 0.875 | K9: AWS (CloudFront/S3) and WordPress | L9: WordPress; Amazon CloudFront; Amazon S3. | M9: — | N9: —
A10: EDU-086 | B10: WP Plugins (Elementor, Forminator, Contact Form 7, Borlabs Cookie, Mailchimp, H5P, Usetiful, Yoast, ACF Pro, 301 Redirects) | C10: Bundled WordPress site comes with essential plugins enabled by default. | D10: Integration · Out-of-the-box | E10: Production | F10: 1 h | G10: 5 | H10: 1 | I10: 16 | J10: 0.938 | K10: Bundled WordPress plugins (several are paid tiers) | L10: WordPress plugins: Elementor, Forminator, Contact Form 7, Borlabs Cookie, Mailchimp, H5P, Usetiful, Yoast, ACF Pro, 301 Redirects. | M10: — | N10: —
B11: Bundle total | G11: =SUM(G7:G10) -> 11 | H11: =SUM(H7:H10) -> 3 | I11: =SUM(I7:I10) -> 72

Sheet B15 Platform Eng & Integrations
A1: B15 · Platform Engineering & Integrations
A2: Pitch: Keep the platform healthy and connected: Sentry monitoring, git and S3 course export and sync, a safe email deadbox for testing, an Open edX API client, plus Canvas and panel-level LTI interoperability.
A3: Offer when the client asks about: DevOps & monitoring · course backups & version control · LMS interoperability (Canvas, LTI) · API access
A4: Pairs well with: B11 (admin)
A6: Solution ID | B6: Feature | C6: What it does | D6: Delivery form | E6: Status | F6: Std deployment time | G6: First-delivery hrs | H6: Repeat config hrs | I6: Original build hrs | J6: Reuse saving % (source) | K6: 3rd-party account required | L6: Integrations / dependencies | M6: Notes & limits | N6: Reference
A7: EDU-034 | B7: Sentry Integration | C7: A Django app plugin that configures the Sentry SDK for Open edX (both the LMS and the CMS). The plugin initializes the SDK from ENV_TOKENS when a DSN is present; when no DSN is configured it is a complete no-op, so it is safe to install everywhere and enable per deployment. | D7: Django App · Custom Plugin | E7: Production | F7: 3 h | G7: 3 | H7: 3 | I7: 60 | J7: 0.95 | K7: Sentry | L7: Sentry (enabled per deployment via DSN). | M7: — | N7: https://github.com/mitodl/open-edx-plugins/tree/main/src/ol_openedx_sentry
A8: EDU-033 | B8: Git Auto Export | C8: An Open edX plugin to auto export courses to GitHub | D8: Django App · Custom Plugin | E8: Production | F8: 3 h | G8: 3 | H8: 3 | I8: 240 | J8: 0.988 | K8: GitHub | L8: GitHub. | M8: — | N8: https://github.com/mitodl/open-edx-plugins/tree/main/src/ol_openedx_git_auto_export
A9: EDU-029 | B9: Course Export S3 Plugin | C9: A django app plugin to add a new API to Open edX to export courses to S3 buckets. | D9: Django App · Custom Plugin | E9: Production | F9: 1 h | G9: 1 | H9: 1 | I9: 60 | J9: 0.983 | K9: AWS | L9: AWS S3. | M9: — | N9: https://github.com/mitodl/open-edx-plugins/tree/main/src/ol_openedx_course_export
A10: EDU-030 | B10: Course Sync | C10: An Open edX plugin to sync course changes to its reruns. | D10: Django App · Custom Plugin | E10: Production | F10: 1 h | G10: 1 | H10: 1 | I10: 120 | J10: 0.992 | K10: — | L10: — | M10: — | N10: https://github.com/mitodl/open-edx-plugins/tree/main/src/ol_openedx_course_sync
A11: EDU-016 | B11: Email Deadbox | C11: Allows to send all emails to a deadbox email address, if dead box is enabled. Useful for testing | D11: Other · Mixed Feature | E11: Production | F11: 1 h | G11: 5 | H11: 1 | I11: 40 | J11: 0.975 | K11: — | L11: Outbound email (SMTP) - all mail redirected to one deadbox address. | M11: — | N11: Toastmasters Azure DevOps (Private)
A12: EDU-037 | B12: Open edX API Client | C12: An API client for Open edX APIs | D12: Django App · Custom Plugin | E12: Production | F12: 1 h | G12: 1 | H12: 1 | I12: 240 | J12: 0.996 | K12: — | L12: Open edX APIs. | M12: — | N12: https://github.com/mitodl/edx-api-client/
A13: EDU-026 | B13: Canvas Integration | C13: A django app plugin to add Canvas integration to Open edX. | D13: Django App · Custom Plugin | E13: Production | F13: 4 h | G13: 4 | H13: 4 | I13: 160 | J13: 0.975 | K13: Canvas | L13: Canvas LMS. | M13: — | N13: https://github.com/mitodl/open-edx-plugins/tree/main/src/ol_openedx_canvas_integration
A14: EDU-066 | B14: LTI Integration in Panel | C14: Admins can override the LTI integrations at an instance or course level via the panel. | D14: Integration · Mixed Feature | E14: Production | F14: 4 h | G14: 16 | H14: 4 | I14: 48 | J14: 0.917 | K14: — | L14: LTI tools (override at instance or course level). | M14: — | N14: —
B15: Bundle total | G15: =SUM(G7:G14) -> 34 | H15: =SUM(H7:H14) -> 18 | I15: =SUM(I7:I14) -> 968

Sheet All Components
A1: All Components — full feature-to-bundle mapping (87 items)
A3: Bundle ID | B3: Bundle | C3: Solution ID | D3: Feature | E3: Category | F3: Sub Category | G3: Status | H3: What it does | I3: First-delivery hrs | J3: Repeat config hrs | K3: Original build hrs | L3: Std deployment time | M3: 3rd-party account | N3: Reference
A4: B01 | B4: Commerce & Monetization | C4: EDU-071 | D4: Stripe Payment Processor | E4: Integration | F4: Out-of-the-box | G4: Production | H4: Payments can be processed via Stripe. | I4: 5 | J4: 1 | K4: 16 | L4: 1 h | M4: Stripe | N4: —
A5: B01 | B5: Commerce & Monetization | C5: EDU-073 | D5: Paypal Payment Processor | E5: Integration | F5: Out-of-the-box | G5: Production | H5: Payments can be processed via PayPal. | I5: 5 | J5: 1 | K5: 16 | L5: 1 h | M5: PayPal | N5: —
A6: B01 | B6: Commerce & Monetization | C6: EDU-069 | D6: Authorizenet Payment Processor | E6: Integration | F6: Out-of-the-box | G6: Production | H6: Payments can be processed via Authorizenet. | I6: 5 | J6: 1 | K6: 16 | L6: 1 h | M6: Authorize.Net | N6: —
A7: B01 | B7: Commerce & Monetization | C7: EDU-070 | D7: Cybersource Payment Processor | E7: Integration | F7: Out-of-the-box | G7: Production | H7: Payments can be processed via Cybersource. | I7: 8 | J7: 2 | K7: 20 | L7: 2 h | M7: Cybersource | N7: —
A8: B01 | B8: Commerce & Monetization | C8: EDU-072 | D8: Cowpay Payment Processor | E8: Integration | F8: Custom Plugin | G8: Production | H8: Payments can be processed via an Egyptian Payment Processor called Cowpay (for the client IQLEAD). | I8: 20 | J8: 4 | K8: 60 | L8: 4 h | M8: Cowpay | N8: —
